Traceback (most recent call last):
  File "/home/provii/Desktop/bitbucketanalysis/venv/lib/python3.6/site-packages/urllib3/connection.py", line 160, in _new_conn
    (self._dns_host, self.port), self.timeout, **extra_kw)
  File "/home/provii/Desktop/bitbucketanalysis/venv/lib/python3.6/site-packages/urllib3/util/connection.py", line 57, in create_connection
    for res in socket.getaddrinfo(host, port, family, socket.SOCK_STREAM):
  File "/home/provii/anaconda3/lib/python3.6/socket.py", line 745, in getaddrinfo
    for res in _socket.getaddrinfo(host, port, family, type, proto, flags):
socket.gaierror: [Errno -2] Name or service not known

During handling of the above exception, another exception occurred:

Traceback (most recent call last):
  File "/home/provii/Desktop/bitbucketanalysis/venv/lib/python3.6/site-packages/urllib3/connectionpool.py", line 603, in urlopen
    chunked=chunked)
  File "/home/provii/Desktop/bitbucketanalysis/venv/lib/python3.6/site-packages/urllib3/connectionpool.py", line 344, in _make_request
    self._validate_conn(conn)
  File "/home/provii/Desktop/bitbucketanalysis/venv/lib/python3.6/site-packages/urllib3/connectionpool.py", line 843, in _validate_conn
    conn.connect()
  File "/home/provii/Desktop/bitbucketanalysis/venv/lib/python3.6/site-packages/urllib3/connection.py", line 316, in connect
    conn = self._new_conn()
  File "/home/provii/Desktop/bitbucketanalysis/venv/lib/python3.6/site-packages/urllib3/connection.py", line 169, in _new_conn
    self, "Failed to establish a new connection: %s" % e)
urllib3.exceptions.NewConnectionError: <urllib3.connection.VerifiedHTTPSConnection object at 0x7f7a06a04390>: Failed to establish a new connection: [Errno -2] Name or service not known

During handling of the above exception, another exception occurred:

Traceback (most recent call last):
  File "/home/provii/Desktop/bitbucketanalysis/venv/lib/python3.6/site-packages/requests/adapters.py", line 449, in send
    timeout=timeout
  File "/home/provii/Desktop/bitbucketanalysis/venv/lib/python3.6/site-packages/urllib3/connectionpool.py", line 641, in urlopen
    _stacktrace=sys.exc_info()[2])
  File "/home/provii/Desktop/bitbucketanalysis/venv/lib/python3.6/site-packages/urllib3/util/retry.py", line 399, in increment
    raise MaxRetryError(_pool, url, error or ResponseError(cause))
urllib3.exceptions.MaxRetryError: HTTPSConnectionPool(host='bitbucket.org', port=443): Max retries exceeded with url: /api/2.0/repositories/PrabinSth/analyticstry2/commits (Caused by NewConnectionError('<urllib3.connection.VerifiedHTTPSConnection object at 0x7f7a06a04390>: Failed to establish a new connection: [Errno -2] Name or service not known',))

During handling of the above exception, another exception occurred:

Traceback (most recent call last):
  File "manage.py", line 21, in <module>
    main()
  File "manage.py", line 17, in main
    execute_from_command_line(sys.argv)
  File "/home/provii/Desktop/bitbucketanalysis/venv/lib/python3.6/site-packages/django/core/management/__init__.py", line 381, in execute_from_command_line
    utility.execute()
  File "/home/provii/Desktop/bitbucketanalysis/venv/lib/python3.6/site-packages/django/core/management/__init__.py", line 375, in execute
    self.fetch_command(subcommand).run_from_argv(self.argv)
  File "/home/provii/Desktop/bitbucketanalysis/venv/lib/python3.6/site-packages/django/core/management/base.py", line 323, in run_from_argv
    self.execute(*args, **cmd_options)
  File "/home/provii/Desktop/bitbucketanalysis/venv/lib/python3.6/site-packages/django/core/management/base.py", line 364, in execute
    output = self.handle(*args, **options)
  File "/home/provii/Desktop/bitbucketanalysis/commit/management/commands/update_commit.py", line 50, in handle
    self.update_commits()
  File "/home/provii/Desktop/bitbucketanalysis/commit/management/commands/update_commit.py", line 30, in update_commits
    headers={'Authorization': 'Bearer {}'.format(social_token.token)}, timeout=10)
  File "/home/provii/Desktop/bitbucketanalysis/venv/lib/python3.6/site-packages/requests/api.py", line 75, in get
    return request('get', url, params=params, **kwargs)
  File "/home/provii/Desktop/bitbucketanalysis/venv/lib/python3.6/site-packages/requests/api.py", line 60, in request
    return session.request(method=method, url=url, **kwargs)
  File "/home/provii/Desktop/bitbucketanalysis/venv/lib/python3.6/site-packages/requests/sessions.py", line 533, in request
    resp = self.send(prep, **send_kwargs)
  File "/home/provii/Desktop/bitbucketanalysis/venv/lib/python3.6/site-packages/requests/sessions.py", line 646, in send
    r = adapter.send(request, **kwargs)
  File "/home/provii/Desktop/bitbucketanalysis/venv/lib/python3.6/site-packages/requests/adapters.py", line 516, in send
    raise ConnectionError(e, request=request)
requests.exceptions.ConnectionError: HTTPSConnectionPool(host='bitbucket.org', port=443): Max retries exceeded with url: /api/2.0/repositories/PrabinSth/analyticstry2/commits (Caused by NewConnectionError('<urllib3.connection.VerifiedHTTPSConnection object at 0x7f7a06a04390>: Failed to establish a new connection: [Errno -2] Name or service not known',))
Traceback (most recent call last):
  File "/home/provii/Desktop/bitbucketanalysis/venv/lib/python3.6/site-packages/urllib3/connection.py", line 160, in _new_conn
    (self._dns_host, self.port), self.timeout, **extra_kw)
  File "/home/provii/Desktop/bitbucketanalysis/venv/lib/python3.6/site-packages/urllib3/util/connection.py", line 57, in create_connection
    for res in socket.getaddrinfo(host, port, family, socket.SOCK_STREAM):
  File "/home/provii/anaconda3/lib/python3.6/socket.py", line 745, in getaddrinfo
    for res in _socket.getaddrinfo(host, port, family, type, proto, flags):
socket.gaierror: [Errno -2] Name or service not known

During handling of the above exception, another exception occurred:

Traceback (most recent call last):
  File "/home/provii/Desktop/bitbucketanalysis/venv/lib/python3.6/site-packages/urllib3/connectionpool.py", line 603, in urlopen
    chunked=chunked)
  File "/home/provii/Desktop/bitbucketanalysis/venv/lib/python3.6/site-packages/urllib3/connectionpool.py", line 344, in _make_request
    self._validate_conn(conn)
  File "/home/provii/Desktop/bitbucketanalysis/venv/lib/python3.6/site-packages/urllib3/connectionpool.py", line 843, in _validate_conn
    conn.connect()
  File "/home/provii/Desktop/bitbucketanalysis/venv/lib/python3.6/site-packages/urllib3/connection.py", line 316, in connect
    conn = self._new_conn()
  File "/home/provii/Desktop/bitbucketanalysis/venv/lib/python3.6/site-packages/urllib3/connection.py", line 169, in _new_conn
    self, "Failed to establish a new connection: %s" % e)
urllib3.exceptions.NewConnectionError: <urllib3.connection.VerifiedHTTPSConnection object at 0x7f700001c358>: Failed to establish a new connection: [Errno -2] Name or service not known

During handling of the above exception, another exception occurred:

Traceback (most recent call last):
  File "/home/provii/Desktop/bitbucketanalysis/venv/lib/python3.6/site-packages/requests/adapters.py", line 449, in send
    timeout=timeout
  File "/home/provii/Desktop/bitbucketanalysis/venv/lib/python3.6/site-packages/urllib3/connectionpool.py", line 641, in urlopen
    _stacktrace=sys.exc_info()[2])
  File "/home/provii/Desktop/bitbucketanalysis/venv/lib/python3.6/site-packages/urllib3/util/retry.py", line 399, in increment
    raise MaxRetryError(_pool, url, error or ResponseError(cause))
urllib3.exceptions.MaxRetryError: HTTPSConnectionPool(host='bitbucket.org', port=443): Max retries exceeded with url: /api/2.0/repositories/PrabinSth/analyticstry2/commits (Caused by NewConnectionError('<urllib3.connection.VerifiedHTTPSConnection object at 0x7f700001c358>: Failed to establish a new connection: [Errno -2] Name or service not known',))

During handling of the above exception, another exception occurred:

Traceback (most recent call last):
  File "manage.py", line 21, in <module>
    main()
  File "manage.py", line 17, in main
    execute_from_command_line(sys.argv)
  File "/home/provii/Desktop/bitbucketanalysis/venv/lib/python3.6/site-packages/django/core/management/__init__.py", line 381, in execute_from_command_line
    utility.execute()
  File "/home/provii/Desktop/bitbucketanalysis/venv/lib/python3.6/site-packages/django/core/management/__init__.py", line 375, in execute
    self.fetch_command(subcommand).run_from_argv(self.argv)
  File "/home/provii/Desktop/bitbucketanalysis/venv/lib/python3.6/site-packages/django/core/management/base.py", line 323, in run_from_argv
    self.execute(*args, **cmd_options)
  File "/home/provii/Desktop/bitbucketanalysis/venv/lib/python3.6/site-packages/django/core/management/base.py", line 364, in execute
    output = self.handle(*args, **options)
  File "/home/provii/Desktop/bitbucketanalysis/commit/management/commands/update_commit.py", line 50, in handle
    self.update_commits()
  File "/home/provii/Desktop/bitbucketanalysis/commit/management/commands/update_commit.py", line 30, in update_commits
    headers={'Authorization': 'Bearer {}'.format(social_token.token)}, timeout=10)
  File "/home/provii/Desktop/bitbucketanalysis/venv/lib/python3.6/site-packages/requests/api.py", line 75, in get
    return request('get', url, params=params, **kwargs)
  File "/home/provii/Desktop/bitbucketanalysis/venv/lib/python3.6/site-packages/requests/api.py", line 60, in request
    return session.request(method=method, url=url, **kwargs)
  File "/home/provii/Desktop/bitbucketanalysis/venv/lib/python3.6/site-packages/requests/sessions.py", line 533, in request
    resp = self.send(prep, **send_kwargs)
  File "/home/provii/Desktop/bitbucketanalysis/venv/lib/python3.6/site-packages/requests/sessions.py", line 646, in send
    r = adapter.send(request, **kwargs)
  File "/home/provii/Desktop/bitbucketanalysis/venv/lib/python3.6/site-packages/requests/adapters.py", line 516, in send
    raise ConnectionError(e, request=request)
requests.exceptions.ConnectionError: HTTPSConnectionPool(host='bitbucket.org', port=443): Max retries exceeded with url: /api/2.0/repositories/PrabinSth/analyticstry2/commits (Caused by NewConnectionError('<urllib3.connection.VerifiedHTTPSConnection object at 0x7f700001c358>: Failed to establish a new connection: [Errno -2] Name or service not known',))
Traceback (most recent call last):
  File "/home/provii/Desktop/bitbucketanalysis/venv/lib/python3.6/site-packages/urllib3/connection.py", line 160, in _new_conn
    (self._dns_host, self.port), self.timeout, **extra_kw)
  File "/home/provii/Desktop/bitbucketanalysis/venv/lib/python3.6/site-packages/urllib3/util/connection.py", line 57, in create_connection
    for res in socket.getaddrinfo(host, port, family, socket.SOCK_STREAM):
  File "/home/provii/anaconda3/lib/python3.6/socket.py", line 745, in getaddrinfo
    for res in _socket.getaddrinfo(host, port, family, type, proto, flags):
socket.gaierror: [Errno -2] Name or service not known

During handling of the above exception, another exception occurred:

Traceback (most recent call last):
  File "/home/provii/Desktop/bitbucketanalysis/venv/lib/python3.6/site-packages/urllib3/connectionpool.py", line 603, in urlopen
    chunked=chunked)
  File "/home/provii/Desktop/bitbucketanalysis/venv/lib/python3.6/site-packages/urllib3/connectionpool.py", line 344, in _make_request
    self._validate_conn(conn)
  File "/home/provii/Desktop/bitbucketanalysis/venv/lib/python3.6/site-packages/urllib3/connectionpool.py", line 843, in _validate_conn
    conn.connect()
  File "/home/provii/Desktop/bitbucketanalysis/venv/lib/python3.6/site-packages/urllib3/connection.py", line 316, in connect
    conn = self._new_conn()
  File "/home/provii/Desktop/bitbucketanalysis/venv/lib/python3.6/site-packages/urllib3/connection.py", line 169, in _new_conn
    self, "Failed to establish a new connection: %s" % e)
urllib3.exceptions.NewConnectionError: <urllib3.connection.VerifiedHTTPSConnection object at 0x7f17f0db0358>: Failed to establish a new connection: [Errno -2] Name or service not known

During handling of the above exception, another exception occurred:

Traceback (most recent call last):
  File "/home/provii/Desktop/bitbucketanalysis/venv/lib/python3.6/site-packages/requests/adapters.py", line 449, in send
    timeout=timeout
  File "/home/provii/Desktop/bitbucketanalysis/venv/lib/python3.6/site-packages/urllib3/connectionpool.py", line 641, in urlopen
    _stacktrace=sys.exc_info()[2])
  File "/home/provii/Desktop/bitbucketanalysis/venv/lib/python3.6/site-packages/urllib3/util/retry.py", line 399, in increment
    raise MaxRetryError(_pool, url, error or ResponseError(cause))
urllib3.exceptions.MaxRetryError: HTTPSConnectionPool(host='bitbucket.org', port=443): Max retries exceeded with url: /api/2.0/repositories/PrabinSth/analyticstry2/commits (Caused by NewConnectionError('<urllib3.connection.VerifiedHTTPSConnection object at 0x7f17f0db0358>: Failed to establish a new connection: [Errno -2] Name or service not known',))

During handling of the above exception, another exception occurred:

Traceback (most recent call last):
  File "manage.py", line 21, in <module>
    main()
  File "manage.py", line 17, in main
    execute_from_command_line(sys.argv)
  File "/home/provii/Desktop/bitbucketanalysis/venv/lib/python3.6/site-packages/django/core/management/__init__.py", line 381, in execute_from_command_line
    utility.execute()
  File "/home/provii/Desktop/bitbucketanalysis/venv/lib/python3.6/site-packages/django/core/management/__init__.py", line 375, in execute
    self.fetch_command(subcommand).run_from_argv(self.argv)
  File "/home/provii/Desktop/bitbucketanalysis/venv/lib/python3.6/site-packages/django/core/management/base.py", line 323, in run_from_argv
    self.execute(*args, **cmd_options)
  File "/home/provii/Desktop/bitbucketanalysis/venv/lib/python3.6/site-packages/django/core/management/base.py", line 364, in execute
    output = self.handle(*args, **options)
  File "/home/provii/Desktop/bitbucketanalysis/commit/management/commands/update_commit.py", line 50, in handle
    self.update_commits()
  File "/home/provii/Desktop/bitbucketanalysis/commit/management/commands/update_commit.py", line 30, in update_commits
    headers={'Authorization': 'Bearer {}'.format(social_token.token)}, timeout=10)
  File "/home/provii/Desktop/bitbucketanalysis/venv/lib/python3.6/site-packages/requests/api.py", line 75, in get
    return request('get', url, params=params, **kwargs)
  File "/home/provii/Desktop/bitbucketanalysis/venv/lib/python3.6/site-packages/requests/api.py", line 60, in request
    return session.request(method=method, url=url, **kwargs)
  File "/home/provii/Desktop/bitbucketanalysis/venv/lib/python3.6/site-packages/requests/sessions.py", line 533, in request
    resp = self.send(prep, **send_kwargs)
  File "/home/provii/Desktop/bitbucketanalysis/venv/lib/python3.6/site-packages/requests/sessions.py", line 646, in send
    r = adapter.send(request, **kwargs)
  File "/home/provii/Desktop/bitbucketanalysis/venv/lib/python3.6/site-packages/requests/adapters.py", line 516, in send
    raise ConnectionError(e, request=request)
requests.exceptions.ConnectionError: HTTPSConnectionPool(host='bitbucket.org', port=443): Max retries exceeded with url: /api/2.0/repositories/PrabinSth/analyticstry2/commits (Caused by NewConnectionError('<urllib3.connection.VerifiedHTTPSConnection object at 0x7f17f0db0358>: Failed to establish a new connection: [Errno -2] Name or service not known',))
Traceback (most recent call last):
  File "/home/provii/Desktop/bitbucketanalysis/venv/lib/python3.6/site-packages/urllib3/connection.py", line 160, in _new_conn
    (self._dns_host, self.port), self.timeout, **extra_kw)
  File "/home/provii/Desktop/bitbucketanalysis/venv/lib/python3.6/site-packages/urllib3/util/connection.py", line 57, in create_connection
    for res in socket.getaddrinfo(host, port, family, socket.SOCK_STREAM):
  File "/home/provii/anaconda3/lib/python3.6/socket.py", line 745, in getaddrinfo
    for res in _socket.getaddrinfo(host, port, family, type, proto, flags):
socket.gaierror: [Errno -2] Name or service not known

During handling of the above exception, another exception occurred:

Traceback (most recent call last):
  File "/home/provii/Desktop/bitbucketanalysis/venv/lib/python3.6/site-packages/urllib3/connectionpool.py", line 603, in urlopen
    chunked=chunked)
  File "/home/provii/Desktop/bitbucketanalysis/venv/lib/python3.6/site-packages/urllib3/connectionpool.py", line 344, in _make_request
    self._validate_conn(conn)
  File "/home/provii/Desktop/bitbucketanalysis/venv/lib/python3.6/site-packages/urllib3/connectionpool.py", line 843, in _validate_conn
    conn.connect()
  File "/home/provii/Desktop/bitbucketanalysis/venv/lib/python3.6/site-packages/urllib3/connection.py", line 316, in connect
    conn = self._new_conn()
  File "/home/provii/Desktop/bitbucketanalysis/venv/lib/python3.6/site-packages/urllib3/connection.py", line 169, in _new_conn
    self, "Failed to establish a new connection: %s" % e)
urllib3.exceptions.NewConnectionError: <urllib3.connection.VerifiedHTTPSConnection object at 0x7fe4e8d4c390>: Failed to establish a new connection: [Errno -2] Name or service not known

During handling of the above exception, another exception occurred:

Traceback (most recent call last):
  File "/home/provii/Desktop/bitbucketanalysis/venv/lib/python3.6/site-packages/requests/adapters.py", line 449, in send
    timeout=timeout
  File "/home/provii/Desktop/bitbucketanalysis/venv/lib/python3.6/site-packages/urllib3/connectionpool.py", line 641, in urlopen
    _stacktrace=sys.exc_info()[2])
  File "/home/provii/Desktop/bitbucketanalysis/venv/lib/python3.6/site-packages/urllib3/util/retry.py", line 399, in increment
    raise MaxRetryError(_pool, url, error or ResponseError(cause))
urllib3.exceptions.MaxRetryError: HTTPSConnectionPool(host='bitbucket.org', port=443): Max retries exceeded with url: /api/2.0/repositories/PrabinSth/analyticstry2/commits (Caused by NewConnectionError('<urllib3.connection.VerifiedHTTPSConnection object at 0x7fe4e8d4c390>: Failed to establish a new connection: [Errno -2] Name or service not known',))

During handling of the above exception, another exception occurred:

Traceback (most recent call last):
  File "manage.py", line 21, in <module>
    main()
  File "manage.py", line 17, in main
    execute_from_command_line(sys.argv)
  File "/home/provii/Desktop/bitbucketanalysis/venv/lib/python3.6/site-packages/django/core/management/__init__.py", line 381, in execute_from_command_line
    utility.execute()
  File "/home/provii/Desktop/bitbucketanalysis/venv/lib/python3.6/site-packages/django/core/management/__init__.py", line 375, in execute
    self.fetch_command(subcommand).run_from_argv(self.argv)
  File "/home/provii/Desktop/bitbucketanalysis/venv/lib/python3.6/site-packages/django/core/management/base.py", line 323, in run_from_argv
    self.execute(*args, **cmd_options)
  File "/home/provii/Desktop/bitbucketanalysis/venv/lib/python3.6/site-packages/django/core/management/base.py", line 364, in execute
    output = self.handle(*args, **options)
  File "/home/provii/Desktop/bitbucketanalysis/commit/management/commands/update_commit.py", line 50, in handle
    self.update_commits()
  File "/home/provii/Desktop/bitbucketanalysis/commit/management/commands/update_commit.py", line 30, in update_commits
    headers={'Authorization': 'Bearer {}'.format(social_token.token)}, timeout=10)
  File "/home/provii/Desktop/bitbucketanalysis/venv/lib/python3.6/site-packages/requests/api.py", line 75, in get
    return request('get', url, params=params, **kwargs)
  File "/home/provii/Desktop/bitbucketanalysis/venv/lib/python3.6/site-packages/requests/api.py", line 60, in request
    return session.request(method=method, url=url, **kwargs)
  File "/home/provii/Desktop/bitbucketanalysis/venv/lib/python3.6/site-packages/requests/sessions.py", line 533, in request
    resp = self.send(prep, **send_kwargs)
  File "/home/provii/Desktop/bitbucketanalysis/venv/lib/python3.6/site-packages/requests/sessions.py", line 646, in send
    r = adapter.send(request, **kwargs)
  File "/home/provii/Desktop/bitbucketanalysis/venv/lib/python3.6/site-packages/requests/adapters.py", line 516, in send
    raise ConnectionError(e, request=request)
requests.exceptions.ConnectionError: HTTPSConnectionPool(host='bitbucket.org', port=443): Max retries exceeded with url: /api/2.0/repositories/PrabinSth/analyticstry2/commits (Caused by NewConnectionError('<urllib3.connection.VerifiedHTTPSConnection object at 0x7fe4e8d4c390>: Failed to establish a new connection: [Errno -2] Name or service not known',))
Traceback (most recent call last):
  File "/home/provii/Desktop/bitbucketanalysis/venv/lib/python3.6/site-packages/urllib3/connection.py", line 160, in _new_conn
    (self._dns_host, self.port), self.timeout, **extra_kw)
  File "/home/provii/Desktop/bitbucketanalysis/venv/lib/python3.6/site-packages/urllib3/util/connection.py", line 57, in create_connection
    for res in socket.getaddrinfo(host, port, family, socket.SOCK_STREAM):
  File "/home/provii/anaconda3/lib/python3.6/socket.py", line 745, in getaddrinfo
    for res in _socket.getaddrinfo(host, port, family, type, proto, flags):
socket.gaierror: [Errno -2] Name or service not known

During handling of the above exception, another exception occurred:

Traceback (most recent call last):
  File "/home/provii/Desktop/bitbucketanalysis/venv/lib/python3.6/site-packages/urllib3/connectionpool.py", line 603, in urlopen
    chunked=chunked)
  File "/home/provii/Desktop/bitbucketanalysis/venv/lib/python3.6/site-packages/urllib3/connectionpool.py", line 344, in _make_request
    self._validate_conn(conn)
  File "/home/provii/Desktop/bitbucketanalysis/venv/lib/python3.6/site-packages/urllib3/connectionpool.py", line 843, in _validate_conn
    conn.connect()
  File "/home/provii/Desktop/bitbucketanalysis/venv/lib/python3.6/site-packages/urllib3/connection.py", line 316, in connect
    conn = self._new_conn()
  File "/home/provii/Desktop/bitbucketanalysis/venv/lib/python3.6/site-packages/urllib3/connection.py", line 169, in _new_conn
    self, "Failed to establish a new connection: %s" % e)
urllib3.exceptions.NewConnectionError: <urllib3.connection.VerifiedHTTPSConnection object at 0x7f7e84670390>: Failed to establish a new connection: [Errno -2] Name or service not known

During handling of the above exception, another exception occurred:

Traceback (most recent call last):
  File "/home/provii/Desktop/bitbucketanalysis/venv/lib/python3.6/site-packages/requests/adapters.py", line 449, in send
    timeout=timeout
  File "/home/provii/Desktop/bitbucketanalysis/venv/lib/python3.6/site-packages/urllib3/connectionpool.py", line 641, in urlopen
    _stacktrace=sys.exc_info()[2])
  File "/home/provii/Desktop/bitbucketanalysis/venv/lib/python3.6/site-packages/urllib3/util/retry.py", line 399, in increment
    raise MaxRetryError(_pool, url, error or ResponseError(cause))
urllib3.exceptions.MaxRetryError: HTTPSConnectionPool(host='bitbucket.org', port=443): Max retries exceeded with url: /api/2.0/repositories/PrabinSth/analyticstry2/commits (Caused by NewConnectionError('<urllib3.connection.VerifiedHTTPSConnection object at 0x7f7e84670390>: Failed to establish a new connection: [Errno -2] Name or service not known',))

During handling of the above exception, another exception occurred:

Traceback (most recent call last):
  File "manage.py", line 21, in <module>
    main()
  File "manage.py", line 17, in main
    execute_from_command_line(sys.argv)
  File "/home/provii/Desktop/bitbucketanalysis/venv/lib/python3.6/site-packages/django/core/management/__init__.py", line 381, in execute_from_command_line
    utility.execute()
  File "/home/provii/Desktop/bitbucketanalysis/venv/lib/python3.6/site-packages/django/core/management/__init__.py", line 375, in execute
    self.fetch_command(subcommand).run_from_argv(self.argv)
  File "/home/provii/Desktop/bitbucketanalysis/venv/lib/python3.6/site-packages/django/core/management/base.py", line 323, in run_from_argv
    self.execute(*args, **cmd_options)
  File "/home/provii/Desktop/bitbucketanalysis/venv/lib/python3.6/site-packages/django/core/management/base.py", line 364, in execute
    output = self.handle(*args, **options)
  File "/home/provii/Desktop/bitbucketanalysis/commit/management/commands/update_commit.py", line 50, in handle
    self.update_commits()
  File "/home/provii/Desktop/bitbucketanalysis/commit/management/commands/update_commit.py", line 30, in update_commits
    headers={'Authorization': 'Bearer {}'.format(social_token.token)}, timeout=10)
  File "/home/provii/Desktop/bitbucketanalysis/venv/lib/python3.6/site-packages/requests/api.py", line 75, in get
    return request('get', url, params=params, **kwargs)
  File "/home/provii/Desktop/bitbucketanalysis/venv/lib/python3.6/site-packages/requests/api.py", line 60, in request
    return session.request(method=method, url=url, **kwargs)
  File "/home/provii/Desktop/bitbucketanalysis/venv/lib/python3.6/site-packages/requests/sessions.py", line 533, in request
    resp = self.send(prep, **send_kwargs)
  File "/home/provii/Desktop/bitbucketanalysis/venv/lib/python3.6/site-packages/requests/sessions.py", line 646, in send
    r = adapter.send(request, **kwargs)
  File "/home/provii/Desktop/bitbucketanalysis/venv/lib/python3.6/site-packages/requests/adapters.py", line 516, in send
    raise ConnectionError(e, request=request)
requests.exceptions.ConnectionError: HTTPSConnectionPool(host='bitbucket.org', port=443): Max retries exceeded with url: /api/2.0/repositories/PrabinSth/analyticstry2/commits (Caused by NewConnectionError('<urllib3.connection.VerifiedHTTPSConnection object at 0x7f7e84670390>: Failed to establish a new connection: [Errno -2] Name or service not known',))
Traceback (most recent call last):
  File "/home/provii/Desktop/bitbucketanalysis/venv/lib/python3.6/site-packages/urllib3/connection.py", line 160, in _new_conn
    (self._dns_host, self.port), self.timeout, **extra_kw)
  File "/home/provii/Desktop/bitbucketanalysis/venv/lib/python3.6/site-packages/urllib3/util/connection.py", line 57, in create_connection
    for res in socket.getaddrinfo(host, port, family, socket.SOCK_STREAM):
  File "/home/provii/anaconda3/lib/python3.6/socket.py", line 745, in getaddrinfo
    for res in _socket.getaddrinfo(host, port, family, type, proto, flags):
socket.gaierror: [Errno -2] Name or service not known

During handling of the above exception, another exception occurred:

Traceback (most recent call last):
  File "/home/provii/Desktop/bitbucketanalysis/venv/lib/python3.6/site-packages/urllib3/connectionpool.py", line 603, in urlopen
    chunked=chunked)
  File "/home/provii/Desktop/bitbucketanalysis/venv/lib/python3.6/site-packages/urllib3/connectionpool.py", line 344, in _make_request
    self._validate_conn(conn)
  File "/home/provii/Desktop/bitbucketanalysis/venv/lib/python3.6/site-packages/urllib3/connectionpool.py", line 843, in _validate_conn
    conn.connect()
  File "/home/provii/Desktop/bitbucketanalysis/venv/lib/python3.6/site-packages/urllib3/connection.py", line 316, in connect
    conn = self._new_conn()
  File "/home/provii/Desktop/bitbucketanalysis/venv/lib/python3.6/site-packages/urllib3/connection.py", line 169, in _new_conn
    self, "Failed to establish a new connection: %s" % e)
urllib3.exceptions.NewConnectionError: <urllib3.connection.VerifiedHTTPSConnection object at 0x7f14a24643c8>: Failed to establish a new connection: [Errno -2] Name or service not known

During handling of the above exception, another exception occurred:

Traceback (most recent call last):
  File "/home/provii/Desktop/bitbucketanalysis/venv/lib/python3.6/site-packages/requests/adapters.py", line 449, in send
    timeout=timeout
  File "/home/provii/Desktop/bitbucketanalysis/venv/lib/python3.6/site-packages/urllib3/connectionpool.py", line 641, in urlopen
    _stacktrace=sys.exc_info()[2])
  File "/home/provii/Desktop/bitbucketanalysis/venv/lib/python3.6/site-packages/urllib3/util/retry.py", line 399, in increment
    raise MaxRetryError(_pool, url, error or ResponseError(cause))
urllib3.exceptions.MaxRetryError: HTTPSConnectionPool(host='bitbucket.org', port=443): Max retries exceeded with url: /api/2.0/repositories/PrabinSth/analyticstry2/commits (Caused by NewConnectionError('<urllib3.connection.VerifiedHTTPSConnection object at 0x7f14a24643c8>: Failed to establish a new connection: [Errno -2] Name or service not known',))

During handling of the above exception, another exception occurred:

Traceback (most recent call last):
  File "manage.py", line 21, in <module>
    main()
  File "manage.py", line 17, in main
    execute_from_command_line(sys.argv)
  File "/home/provii/Desktop/bitbucketanalysis/venv/lib/python3.6/site-packages/django/core/management/__init__.py", line 381, in execute_from_command_line
    utility.execute()
  File "/home/provii/Desktop/bitbucketanalysis/venv/lib/python3.6/site-packages/django/core/management/__init__.py", line 375, in execute
    self.fetch_command(subcommand).run_from_argv(self.argv)
  File "/home/provii/Desktop/bitbucketanalysis/venv/lib/python3.6/site-packages/django/core/management/base.py", line 323, in run_from_argv
    self.execute(*args, **cmd_options)
  File "/home/provii/Desktop/bitbucketanalysis/venv/lib/python3.6/site-packages/django/core/management/base.py", line 364, in execute
    output = self.handle(*args, **options)
  File "/home/provii/Desktop/bitbucketanalysis/commit/management/commands/update_commit.py", line 50, in handle
    self.update_commits()
  File "/home/provii/Desktop/bitbucketanalysis/commit/management/commands/update_commit.py", line 30, in update_commits
    headers={'Authorization': 'Bearer {}'.format(social_token.token)}, timeout=10)
  File "/home/provii/Desktop/bitbucketanalysis/venv/lib/python3.6/site-packages/requests/api.py", line 75, in get
    return request('get', url, params=params, **kwargs)
  File "/home/provii/Desktop/bitbucketanalysis/venv/lib/python3.6/site-packages/requests/api.py", line 60, in request
    return session.request(method=method, url=url, **kwargs)
  File "/home/provii/Desktop/bitbucketanalysis/venv/lib/python3.6/site-packages/requests/sessions.py", line 533, in request
    resp = self.send(prep, **send_kwargs)
  File "/home/provii/Desktop/bitbucketanalysis/venv/lib/python3.6/site-packages/requests/sessions.py", line 646, in send
    r = adapter.send(request, **kwargs)
  File "/home/provii/Desktop/bitbucketanalysis/venv/lib/python3.6/site-packages/requests/adapters.py", line 516, in send
    raise ConnectionError(e, request=request)
requests.exceptions.ConnectionError: HTTPSConnectionPool(host='bitbucket.org', port=443): Max retries exceeded with url: /api/2.0/repositories/PrabinSth/analyticstry2/commits (Caused by NewConnectionError('<urllib3.connection.VerifiedHTTPSConnection object at 0x7f14a24643c8>: Failed to establish a new connection: [Errno -2] Name or service not known',))
Traceback (most recent call last):
  File "manage.py", line 21, in <module>
    main()
  File "manage.py", line 17, in main
    execute_from_command_line(sys.argv)
  File "/home/provii/Desktop/bitbucketanalysis/venv/lib/python3.6/site-packages/django/core/management/__init__.py", line 381, in execute_from_command_line
    utility.execute()
  File "/home/provii/Desktop/bitbucketanalysis/venv/lib/python3.6/site-packages/django/core/management/__init__.py", line 375, in execute
    self.fetch_command(subcommand).run_from_argv(self.argv)
  File "/home/provii/Desktop/bitbucketanalysis/venv/lib/python3.6/site-packages/django/core/management/base.py", line 323, in run_from_argv
    self.execute(*args, **cmd_options)
  File "/home/provii/Desktop/bitbucketanalysis/venv/lib/python3.6/site-packages/django/core/management/base.py", line 361, in execute
    self.check()
  File "/home/provii/Desktop/bitbucketanalysis/venv/lib/python3.6/site-packages/django/core/management/base.py", line 390, in check
    include_deployment_checks=include_deployment_checks,
  File "/home/provii/Desktop/bitbucketanalysis/venv/lib/python3.6/site-packages/django/core/management/base.py", line 377, in _run_checks
    return checks.run_checks(**kwargs)
  File "/home/provii/Desktop/bitbucketanalysis/venv/lib/python3.6/site-packages/django/core/checks/registry.py", line 72, in run_checks
    new_errors = check(app_configs=app_configs)
  File "/home/provii/Desktop/bitbucketanalysis/venv/lib/python3.6/site-packages/django/core/checks/urls.py", line 13, in check_url_config
    return check_resolver(resolver)
  File "/home/provii/Desktop/bitbucketanalysis/venv/lib/python3.6/site-packages/django/core/checks/urls.py", line 23, in check_resolver
    return check_method()
  File "/home/provii/Desktop/bitbucketanalysis/venv/lib/python3.6/site-packages/django/urls/resolvers.py", line 399, in check
    for pattern in self.url_patterns:
  File "/home/provii/Desktop/bitbucketanalysis/venv/lib/python3.6/site-packages/django/utils/functional.py", line 80, in __get__
    res = instance.__dict__[self.name] = self.func(instance)
  File "/home/provii/Desktop/bitbucketanalysis/venv/lib/python3.6/site-packages/django/urls/resolvers.py", line 584, in url_patterns
    patterns = getattr(self.urlconf_module, "urlpatterns", self.urlconf_module)
  File "/home/provii/Desktop/bitbucketanalysis/venv/lib/python3.6/site-packages/django/utils/functional.py", line 80, in __get__
    res = instance.__dict__[self.name] = self.func(instance)
  File "/home/provii/Desktop/bitbucketanalysis/venv/lib/python3.6/site-packages/django/urls/resolvers.py", line 577, in urlconf_module
    return import_module(self.urlconf_name)
  File "/home/provii/Desktop/bitbucketanalysis/venv/lib/python3.6/importlib/__init__.py", line 126, in import_module
    return _bootstrap._gcd_import(name[level:], package, level)
  File "<frozen importlib._bootstrap>", line 994, in _gcd_import
  File "<frozen importlib._bootstrap>", line 971, in _find_and_load
  File "<frozen importlib._bootstrap>", line 955, in _find_and_load_unlocked
  File "<frozen importlib._bootstrap>", line 665, in _load_unlocked
  File "<frozen importlib._bootstrap_external>", line 678, in exec_module
  File "<frozen importlib._bootstrap>", line 219, in _call_with_frames_removed
  File "/home/provii/Desktop/bitbucketanalysis/BitBucketAnalyticsProject/urls.py", line 29, in <module>
    path('',include('commit.urls'))
  File "/home/provii/Desktop/bitbucketanalysis/venv/lib/python3.6/site-packages/django/urls/conf.py", line 34, in include
    urlconf_module = import_module(urlconf_module)
  File "/home/provii/Desktop/bitbucketanalysis/venv/lib/python3.6/importlib/__init__.py", line 126, in import_module
    return _bootstrap._gcd_import(name[level:], package, level)
  File "<frozen importlib._bootstrap>", line 994, in _gcd_import
  File "<frozen importlib._bootstrap>", line 971, in _find_and_load
  File "<frozen importlib._bootstrap>", line 955, in _find_and_load_unlocked
  File "<frozen importlib._bootstrap>", line 665, in _load_unlocked
  File "<frozen importlib._bootstrap_external>", line 678, in exec_module
  File "<frozen importlib._bootstrap>", line 219, in _call_with_frames_removed
  File "/home/provii/Desktop/bitbucketanalysis/commit/urls.py", line 3, in <module>
    from commit import views
  File "/home/provii/Desktop/bitbucketanalysis/commit/views.py", line 17
    return Commit.objects.filter(slug=slug).
                                           ^
SyntaxError: invalid syntax
